Workbook
Name Categories: '⚙️ Settings'!$B$8:$B$24
Name CatIcons: '⚙️ Settings'!$B$8:$C$24
Name IncomeSources: '⚙️ Settings'!$D$8:$D$14
Name PayMethods: '⚙️ Settings'!$E$8:$E$12
Name Accounts: '⚙️ Settings'!$F$8:$F$11

Sheet 🏠 Dashboard
B2: 🏠 Dashboard
B3: Your month at a glance — pick a month below and every number follows
B6: VIEWING MONTH | C6: 46204 | D6: ← type any date in a month (e.g. 6/1/2026) to travel there
B8: 💰 INCOME | D8: 💸 EXPENSES | F8: 💼 NET | H8: 🌱 SAVINGS RATE
B9: =SUMIFS('💳 Transactions'!$I$12:$I$5000,'💳 Transactions'!$B$12:$B$5000,">="&'🏠 Dashboard'!$C$6,'💳 Transactions'!$B$12:$B$5000,"<"&EOMONTH('🏠 Dashboard'!$C$6,0)+1) | D9: =SUMIFS('💳 Transactions'!$J$12:$J$5000,'💳 Transactions'!$B$12:$B$5000,">="&'🏠 Dashboard'!$C$6,'💳 Transactions'!$B$12:$B$5000,"<"&EOMONTH('🏠 Dashboard'!$C$6,0)+1) | F9: =SUMIFS('💳 Transactions'!$I$12:$I$5000,'💳 Transactions'!$B$12:$B$5000,">="&'🏠 Dashboard'!$C$6,'💳 Transactions'!$B$12:$B$5000,"<"&EOMONTH('🏠 Dashboard'!$C$6,0)+1)-SUMIFS('💳 Transactions'!$J$12:$J$5000,'💳 Transactions'!$B$12:$B$5000,">="&'🏠 Dashboard'!$C$6,'💳 Transactions'!$B$12:$B$5000,"<"&EOMONTH('🏠 Dashboard'!$C$6,0)+1) | H9: =IFERROR((SUMIFS('💳 Transactions'!$J$12:$J$5000,'💳 Transactions'!$E$12:$E$5000,"Savings",'💳 Transactions'!$B$12:$B$5000,">="&'🏠 Dashboard'!$C$6,'💳 Transactions'!$B$12:$B$5000,"<"&EOMONTH('🏠 Dashboard'!$C$6,0)+1)+SUMIFS('💳 Transactions'!$J$12:$J$5000,'💳 Transactions'!$E$12:$E$5000,"Investments",'💳 Transactions'!$B$12:$B$5000,">="&'🏠 Dashboard'!$C$6,'💳 Transactions'!$B$12:$B$5000,"<"&EOMONTH('🏠 Dashboard'!$C$6,0)+1)+SUMIFS('💳 Transactions'!$I$12:$I$5000,'💳 Transactions'!$B$12:$B$5000,">="&'🏠 Dashboard'!$C$6,'💳 Transactions'!$B$12:$B$5000,"<"&EOMONTH('🏠 Dashboard'!$C$6,0)+1)-SUMIFS('💳 Transactions'!$J$12:$J$5000,'💳 Transactions'!$B$12:$B$5000,">="&'🏠 Dashboard'!$C$6,'💳 Transactions'!$B$12:$B$5000,"<"&EOMONTH('🏠 Dashboard'!$C$6,0)+1))/SUMIFS('💳 Transactions'!$I$12:$I$5000,'💳 Transactions'!$B$12:$B$5000,">="&'🏠 Dashboard'!$C$6,'💳 Transactions'!$B$12:$B$5000,"<"&EOMONTH('🏠 Dashboard'!$C$6,0)+1),0)
B11: ="vs "&TEXT(SUMIFS('💳 Transactions'!$I$12:$I$5000,'💳 Transactions'!$B$12:$B$5000,">="&EDATE('🏠 Dashboard'!$C$6,-1),'💳 Transactions'!$B$12:$B$5000,"<"&'🏠 Dashboard'!$C$6),"$#,##0")&" last month" | D11: ="vs "&TEXT(SUMIFS('💳 Transactions'!$J$12:$J$5000,'💳 Transactions'!$B$12:$B$5000,">="&EDATE('🏠 Dashboard'!$C$6,-1),'💳 Transactions'!$B$12:$B$5000,"<"&'🏠 Dashboard'!$C$6),"$#,##0")&" last month" | F11: ="Income − expenses" | H11: ="Saved + invested + leftover"
B13: WHERE THE MONEY WENT | N13: CHART DATA (auto — no need to touch)
B14: CATEGORY | C14: SPENT | D14: % OF SPEND
B15: 🏠 Housing | C15: =SUMIFS('💳 Transactions'!$J$12:$J$5000,'💳 Transactions'!$E$12:$E$5000,"Housing",'💳 Transactions'!$B$12:$B$5000,">="&'🏠 Dashboard'!$C$6,'💳 Transactions'!$B$12:$B$5000,"<"&EOMONTH('🏠 Dashboard'!$C$6,0)+1) | D15: =IFERROR($C15/SUMIFS('💳 Transactions'!$J$12:$J$5000,'💳 Transactions'!$B$12:$B$5000,">="&'🏠 Dashboard'!$C$6,'💳 Transactions'!$B$12:$B$5000,"<"&EOMONTH('🏠 Dashboard'!$C$6,0)+1),0) | E15: =REPT("█",ROUND(MAX(0,MIN(1,$C15/MAX($C$15:$C$30)))*10,0))&REPT("░",10-ROUND(MAX(0,MIN(1,$C15/MAX($C$15:$C$30)))*10,0)) | N15: Housing | O15: =SUMIFS('💳 Transactions'!$J$12:$J$5000,'💳 Transactions'!$E$12:$E$5000,"Housing",'💳 Transactions'!$B$12:$B$5000,">="&'🏠 Dashboard'!$C$6,'💳 Transactions'!$B$12:$B$5000,"<"&EOMONTH('🏠 Dashboard'!$C$6,0)+1)+ROW()/10000000 | Q15: =INDEX($N$15:$N$30,MATCH(LARGE($O$15:$O$30,1),$O$15:$O$30,0)) | R15: =ROUND(LARGE($O$15:$O$30,1),2)
B16: 🍽️ Food | C16: =SUMIFS('💳 Transactions'!$J$12:$J$5000,'💳 Transactions'!$E$12:$E$5000,"Food",'💳 Transactions'!$B$12:$B$5000,">="&'🏠 Dashboard'!$C$6,'💳 Transactions'!$B$12:$B$5000,"<"&EOMONTH('🏠 Dashboard'!$C$6,0)+1) | D16: =IFERROR($C16/SUMIFS('💳 Transactions'!$J$12:$J$5000,'💳 Transactions'!$B$12:$B$5000,">="&'🏠 Dashboard'!$C$6,'💳 Transactions'!$B$12:$B$5000,"<"&EOMONTH('🏠 Dashboard'!$C$6,0)+1),0) | E16: =REPT("█",ROUND(MAX(0,MIN(1,$C16/MAX($C$15:$C$30)))*10,0))&REPT("░",10-ROUND(MAX(0,MIN(1,$C16/MAX($C$15:$C$30)))*10,0)) | N16: Food | O16: =SUMIFS('💳 Transactions'!$J$12:$J$5000,'💳 Transactions'!$E$12:$E$5000,"Food",'💳 Transactions'!$B$12:$B$5000,">="&'🏠 Dashboard'!$C$6,'💳 Transactions'!$B$12:$B$5000,"<"&EOMONTH('🏠 Dashboard'!$C$6,0)+1)+ROW()/10000000 | Q16: =INDEX($N$15:$N$30,MATCH(LARGE($O$15:$O$30,2),$O$15:$O$30,0)) | R16: =ROUND(LARGE($O$15:$O$30,2),2)
B17: 🚗 Transportation | C17: =SUMIFS('💳 Transactions'!$J$12:$J$5000,'💳 Transactions'!$E$12:$E$5000,"Transportation",'💳 Transactions'!$B$12:$B$5000,">="&'🏠 Dashboard'!$C$6,'💳 Transactions'!$B$12:$B$5000,"<"&EOMONTH('🏠 Dashboard'!$C$6,0)+1) | D17: =IFERROR($C17/SUMIFS('💳 Transactions'!$J$12:$J$5000,'💳 Transactions'!$B$12:$B$5000,">="&'🏠 Dashboard'!$C$6,'💳 Transactions'!$B$12:$B$5000,"<"&EOMONTH('🏠 Dashboard'!$C$6,0)+1),0) | E17: =REPT("█",ROUND(MAX(0,MIN(1,$C17/MAX($C$15:$C$30)))*10,0))&REPT("░",10-ROUND(MAX(0,MIN(1,$C17/MAX($C$15:$C$30)))*10,0)) | N17: Transportation | O17: =SUMIFS('💳 Transactions'!$J$12:$J$5000,'💳 Transactions'!$E$12:$E$5000,"Transportation",'💳 Transactions'!$B$12:$B$5000,">="&'🏠 Dashboard'!$C$6,'💳 Transactions'!$B$12:$B$5000,"<"&EOMONTH('🏠 Dashboard'!$C$6,0)+1)+ROW()/10000000 | Q17: =INDEX($N$15:$N$30,MATCH(LARGE($O$15:$O$30,3),$O$15:$O$30,0)) | R17: =ROUND(LARGE($O$15:$O$30,3),2)
B18: 🛍️ Shopping | C18: =SUMIFS('💳 Transactions'!$J$12:$J$5000,'💳 Transactions'!$E$12:$E$5000,"Shopping",'💳 Transactions'!$B$12:$B$5000,">="&'🏠 Dashboard'!$C$6,'💳 Transactions'!$B$12:$B$5000,"<"&EOMONTH('🏠 Dashboard'!$C$6,0)+1) | D18: =IFERROR($C18/SUMIFS('💳 Transactions'!$J$12:$J$5000,'💳 Transactions'!$B$12:$B$5000,">="&'🏠 Dashboard'!$C$6,'💳 Transactions'!$B$12:$B$5000,"<"&EOMONTH('🏠 Dashboard'!$C$6,0)+1),0) | E18: =REPT("█",ROUND(MAX(0,MIN(1,$C18/MAX($C$15:$C$30)))*10,0))&REPT("░",10-ROUND(MAX(0,MIN(1,$C18/MAX($C$15:$C$30)))*10,0)) | N18: Shopping | O18: =SUMIFS('💳 Transactions'!$J$12:$J$5000,'💳 Transactions'!$E$12:$E$5000,"Shopping",'💳 Transactions'!$B$12:$B$5000,">="&'🏠 Dashboard'!$C$6,'💳 Transactions'!$B$12:$B$5000,"<"&EOMONTH('🏠 Dashboard'!$C$6,0)+1)+ROW()/10000000 | Q18: =INDEX($N$15:$N$30,MATCH(LARGE($O$15:$O$30,4),$O$15:$O$30,0)) | R18: =ROUND(LARGE($O$15:$O$30,4),2)
B19: 🎬 Entertainment | C19: =SUMIFS('💳 Transactions'!$J$12:$J$5000,'💳 Transactions'!$E$12:$E$5000,"Entertainment",'💳 Transactions'!$B$12:$B$5000,">="&'🏠 Dashboard'!$C$6,'💳 Transactions'!$B$12:$B$5000,"<"&EOMONTH('🏠 Dashboard'!$C$6,0)+1) | D19: =IFERROR($C19/SUMIFS('💳 Transactions'!$J$12:$J$5000,'💳 Transactions'!$B$12:$B$5000,">="&'🏠 Dashboard'!$C$6,'💳 Transactions'!$B$12:$B$5000,"<"&EOMONTH('🏠 Dashboard'!$C$6,0)+1),0) | E19: =REPT("█",ROUND(MAX(0,MIN(1,$C19/MAX($C$15:$C$30)))*10,0))&REPT("░",10-ROUND(MAX(0,MIN(1,$C19/MAX($C$15:$C$30)))*10,0)) | N19: Entertainment | O19: =SUMIFS('💳 Transactions'!$J$12:$J$5000,'💳 Transactions'!$E$12:$E$5000,"Entertainment",'💳 Transactions'!$B$12:$B$5000,">="&'🏠 Dashboard'!$C$6,'💳 Transactions'!$B$12:$B$5000,"<"&EOMONTH('🏠 Dashboard'!$C$6,0)+1)+ROW()/10000000 | Q19: =INDEX($N$15:$N$30,MATCH(LARGE($O$15:$O$30,5),$O$15:$O$30,0)) | R19: =ROUND(LARGE($O$15:$O$30,5),2)
B20: 🩺 Health | C20: =SUMIFS('💳 Transactions'!$J$12:$J$5000,'💳 Transactions'!$E$12:$E$5000,"Health",'💳 Transactions'!$B$12:$B$5000,">="&'🏠 Dashboard'!$C$6,'💳 Transactions'!$B$12:$B$5000,"<"&EOMONTH('🏠 Dashboard'!$C$6,0)+1) | D20: =IFERROR($C20/SUMIFS('💳 Transactions'!$J$12:$J$5000,'💳 Transactions'!$B$12:$B$5000,">="&'🏠 Dashboard'!$C$6,'💳 Transactions'!$B$12:$B$5000,"<"&EOMONTH('🏠 Dashboard'!$C$6,0)+1),0) | E20: =REPT("█",ROUND(MAX(0,MIN(1,$C20/MAX($C$15:$C$30)))*10,0))&REPT("░",10-ROUND(MAX(0,MIN(1,$C20/MAX($C$15:$C$30)))*10,0)) | N20: Health | O20: =SUMIFS('💳 Transactions'!$J$12:$J$5000,'💳 Transactions'!$E$12:$E$5000,"Health",'💳 Transactions'!$B$12:$B$5000,">="&'🏠 Dashboard'!$C$6,'💳 Transactions'!$B$12:$B$5000,"<"&EOMONTH('🏠 Dashboard'!$C$6,0)+1)+ROW()/10000000 | Q20: Other | R20: =MAX(0,ROUND(SUMIFS('💳 Transactions'!$J$12:$J$5000,'💳 Transactions'!$B$12:$B$5000,">="&'🏠 Dashboard'!$C$6,'💳 Transactions'!$B$12:$B$5000,"<"&EOMONTH('🏠 Dashboard'!$C$6,0)+1)-SUM($R$15:$R$19),2))
B21: 🛡️ Insurance | C21: =SUMIFS('💳 Transactions'!$J$12:$J$5000,'💳 Transactions'!$E$12:$E$5000,"Insurance",'💳 Transactions'!$B$12:$B$5000,">="&'🏠 Dashboard'!$C$6,'💳 Transactions'!$B$12:$B$5000,"<"&EOMONTH('🏠 Dashboard'!$C$6,0)+1) | D21: =IFERROR($C21/SUMIFS('💳 Transactions'!$J$12:$J$5000,'💳 Transactions'!$B$12:$B$5000,">="&'🏠 Dashboard'!$C$6,'💳 Transactions'!$B$12:$B$5000,"<"&EOMONTH('🏠 Dashboard'!$C$6,0)+1),0) | E21: =REPT("█",ROUND(MAX(0,MIN(1,$C21/MAX($C$15:$C$30)))*10,0))&REPT("░",10-ROUND(MAX(0,MIN(1,$C21/MAX($C$15:$C$30)))*10,0)) | N21: Insurance | O21: =SUMIFS('💳 Transactions'!$J$12:$J$5000,'💳 Transactions'!$E$12:$E$5000,"Insurance",'💳 Transactions'!$B$12:$B$5000,">="&'🏠 Dashboard'!$C$6,'💳 Transactions'!$B$12:$B$5000,"<"&EOMONTH('🏠 Dashboard'!$C$6,0)+1)+ROW()/10000000
B22: ✈️ Travel | C22: =SUMIFS('💳 Transactions'!$J$12:$J$5000,'💳 Transactions'!$E$12:$E$5000,"Travel",'💳 Transactions'!$B$12:$B$5000,">="&'🏠 Dashboard'!$C$6,'💳 Transactions'!$B$12:$B$5000,"<"&EOMONTH('🏠 Dashboard'!$C$6,0)+1) | D22: =IFERROR($C22/SUMIFS('💳 Transactions'!$J$12:$J$5000,'💳 Transactions'!$B$12:$B$5000,">="&'🏠 Dashboard'!$C$6,'💳 Transactions'!$B$12:$B$5000,"<"&EOMONTH('🏠 Dashboard'!$C$6,0)+1),0) | E22: =REPT("█",ROUND(MAX(0,MIN(1,$C22/MAX($C$15:$C$30)))*10,0))&REPT("░",10-ROUND(MAX(0,MIN(1,$C22/MAX($C$15:$C$30)))*10,0)) | N22: Travel | O22: =SUMIFS('💳 Transactions'!$J$12:$J$5000,'💳 Transactions'!$E$12:$E$5000,"Travel",'💳 Transactions'!$B$12:$B$5000,">="&'🏠 Dashboard'!$C$6,'💳 Transactions'!$B$12:$B$5000,"<"&EOMONTH('🏠 Dashboard'!$C$6,0)+1)+ROW()/10000000
B23: 🎓 Education | C23: =SUMIFS('💳 Transactions'!$J$12:$J$5000,'💳 Transactions'!$E$12:$E$5000,"Education",'💳 Transactions'!$B$12:$B$5000,">="&'🏠 Dashboard'!$C$6,'💳 Transactions'!$B$12:$B$5000,"<"&EOMONTH('🏠 Dashboard'!$C$6,0)+1) | D23: =IFERROR($C23/SUMIFS('💳 Transactions'!$J$12:$J$5000,'💳 Transactions'!$B$12:$B$5000,">="&'🏠 Dashboard'!$C$6,'💳 Transactions'!$B$12:$B$5000,"<"&EOMONTH('🏠 Dashboard'!$C$6,0)+1),0) | E23: =REPT("█",ROUND(MAX(0,MIN(1,$C23/MAX($C$15:$C$30)))*10,0))&REPT("░",10-ROUND(MAX(0,MIN(1,$C23/MAX($C$15:$C$30)))*10,0)) | N23: Education | O23: =SUMIFS('💳 Transactions'!$J$12:$J$5000,'💳 Transactions'!$E$12:$E$5000,"Education",'💳 Transactions'!$B$12:$B$5000,">="&'🏠 Dashboard'!$C$6,'💳 Transactions'!$B$12:$B$5000,"<"&EOMONTH('🏠 Dashboard'!$C$6,0)+1)+ROW()/10000000
B24: 🔁 Subscriptions | C24: =SUMIFS('💳 Transactions'!$J$12:$J$5000,'💳 Transactions'!$E$12:$E$5000,"Subscriptions",'💳 Transactions'!$B$12:$B$5000,">="&'🏠 Dashboard'!$C$6,'💳 Transactions'!$B$12:$B$5000,"<"&EOMONTH('🏠 Dashboard'!$C$6,0)+1) | D24: =IFERROR($C24/SUMIFS('💳 Transactions'!$J$12:$J$5000,'💳 Transactions'!$B$12:$B$5000,">="&'🏠 Dashboard'!$C$6,'💳 Transactions'!$B$12:$B$5000,"<"&EOMONTH('🏠 Dashboard'!$C$6,0)+1),0) | E24: =REPT("█",ROUND(MAX(0,MIN(1,$C24/MAX($C$15:$C$30)))*10,0))&REPT("░",10-ROUND(MAX(0,MIN(1,$C24/MAX($C$15:$C$30)))*10,0)) | N24: Subscriptions | O24: =SUMIFS('💳 Transactions'!$J$12:$J$5000,'💳 Transactions'!$E$12:$E$5000,"Subscriptions",'💳 Transactions'!$B$12:$B$5000,">="&'🏠 Dashboard'!$C$6,'💳 Transactions'!$B$12:$B$5000,"<"&EOMONTH('🏠 Dashboard'!$C$6,0)+1)+ROW()/10000000
B25: 🐾 Pets | C25: =SUMIFS('💳 Transactions'!$J$12:$J$5000,'💳 Transactions'!$E$12:$E$5000,"Pets",'💳 Transactions'!$B$12:$B$5000,">="&'🏠 Dashboard'!$C$6,'💳 Transactions'!$B$12:$B$5000,"<"&EOMONTH('🏠 Dashboard'!$C$6,0)+1) | D25: =IFERROR($C25/SUMIFS('💳 Transactions'!$J$12:$J$5000,'💳 Transactions'!$B$12:$B$5000,">="&'🏠 Dashboard'!$C$6,'💳 Transactions'!$B$12:$B$5000,"<"&EOMONTH('🏠 Dashboard'!$C$6,0)+1),0) | E25: =REPT("█",ROUND(MAX(0,MIN(1,$C25/MAX($C$15:$C$30)))*10,0))&REPT("░",10-ROUND(MAX(0,MIN(1,$C25/MAX($C$15:$C$30)))*10,0)) | N25: Pets | O25: =SUMIFS('💳 Transactions'!$J$12:$J$5000,'💳 Transactions'!$E$12:$E$5000,"Pets",'💳 Transactions'!$B$12:$B$5000,">="&'🏠 Dashboard'!$C$6,'💳 Transactions'!$B$12:$B$5000,"<"&EOMONTH('🏠 Dashboard'!$C$6,0)+1)+ROW()/10000000
B26: 🧸 Children | C26: =SUMIFS('💳 Transactions'!$J$12:$J$5000,'💳 Transactions'!$E$12:$E$5000,"Children",'💳 Transactions'!$B$12:$B$5000,">="&'🏠 Dashboard'!$C$6,'💳 Transactions'!$B$12:$B$5000,"<"&EOMONTH('🏠 Dashboard'!$C$6,0)+1) | D26: =IFERROR($C26/SUMIFS('💳 Transactions'!$J$12:$J$5000,'💳 Transactions'!$B$12:$B$5000,">="&'🏠 Dashboard'!$C$6,'💳 Transactions'!$B$12:$B$5000,"<"&EOMONTH('🏠 Dashboard'!$C$6,0)+1),0) | E26: =REPT("█",ROUND(MAX(0,MIN(1,$C26/MAX($C$15:$C$30)))*10,0))&REPT("░",10-ROUND(MAX(0,MIN(1,$C26/MAX($C$15:$C$30)))*10,0)) | N26: Children | O26: =SUMIFS('💳 Transactions'!$J$12:$J$5000,'💳 Transactions'!$E$12:$E$5000,"Children",'💳 Transactions'!$B$12:$B$5000,">="&'🏠 Dashboard'!$C$6,'💳 Transactions'!$B$12:$B$5000,"<"&EOMONTH('🏠 Dashboard'!$C$6,0)+1)+ROW()/10000000
B27: 🏛️ Taxes | C27: =SUMIFS('💳 Transactions'!$J$12:$J$5000,'💳 Transactions'!$E$12:$E$5000,"Taxes",'💳 Transactions'!$B$12:$B$5000,">="&'🏠 Dashboard'!$C$6,'💳 Transactions'!$B$12:$B$5000,"<"&EOMONTH('🏠 Dashboard'!$C$6,0)+1) | D27: =IFERROR($C27/SUMIFS('💳 Transactions'!$J$12:$J$5000,'💳 Transactions'!$B$12:$B$5000,">="&'🏠 Dashboard'!$C$6,'💳 Transactions'!$B$12:$B$5000,"<"&EOMONTH('🏠 Dashboard'!$C$6,0)+1),0) | E27: =REPT("█",ROUND(MAX(0,MIN(1,$C27/MAX($C$15:$C$30)))*10,0))&REPT("░",10-ROUND(MAX(0,MIN(1,$C27/MAX($C$15:$C$30)))*10,0)) | N27: Taxes | O27: =SUMIFS('💳 Transactions'!$J$12:$J$5000,'💳 Transactions'!$E$12:$E$5000,"Taxes",'💳 Transactions'!$B$12:$B$5000,">="&'🏠 Dashboard'!$C$6,'💳 Transactions'!$B$12:$B$5000,"<"&EOMONTH('🏠 Dashboard'!$C$6,0)+1)+ROW()/10000000
B28: 🌱 Savings | C28: =SUMIFS('💳 Transactions'!$J$12:$J$5000,'💳 Transactions'!$E$12:$E$5000,"Savings",'💳 Transactions'!$B$12:$B$5000,">="&'🏠 Dashboard'!$C$6,'💳 Transactions'!$B$12:$B$5000,"<"&EOMONTH('🏠 Dashboard'!$C$6,0)+1) | D28: =IFERROR($C28/SUMIFS('💳 Transactions'!$J$12:$J$5000,'💳 Transactions'!$B$12:$B$5000,">="&'🏠 Dashboard'!$C$6,'💳 Transactions'!$B$12:$B$5000,"<"&EOMONTH('🏠 Dashboard'!$C$6,0)+1),0) | E28: =REPT("█",ROUND(MAX(0,MIN(1,$C28/MAX($C$15:$C$30)))*10,0))&REPT("░",10-ROUND(MAX(0,MIN(1,$C28/MAX($C$15:$C$30)))*10,0)) | N28: Savings | O28: =SUMIFS('💳 Transactions'!$J$12:$J$5000,'💳 Transactions'!$E$12:$E$5000,"Savings",'💳 Transactions'!$B$12:$B$5000,">="&'🏠 Dashboard'!$C$6,'💳 Transactions'!$B$12:$B$5000,"<"&EOMONTH('🏠 Dashboard'!$C$6,0)+1)+ROW()/10000000
B29: 📈 Investments | C29: =SUMIFS('💳 Transactions'!$J$12:$J$5000,'💳 Transactions'!$E$12:$E$5000,"Investments",'💳 Transactions'!$B$12:$B$5000,">="&'🏠 Dashboard'!$C$6,'💳 Transactions'!$B$12:$B$5000,"<"&EOMONTH('🏠 Dashboard'!$C$6,0)+1) | D29: =IFERROR($C29/SUMIFS('💳 Transactions'!$J$12:$J$5000,'💳 Transactions'!$B$12:$B$5000,">="&'🏠 Dashboard'!$C$6,'💳 Transactions'!$B$12:$B$5000,"<"&EOMONTH('🏠 Dashboard'!$C$6,0)+1),0) | E29: =REPT("█",ROUND(MAX(0,MIN(1,$C29/MAX($C$15:$C$30)))*10,0))&REPT("░",10-ROUND(MAX(0,MIN(1,$C29/MAX($C$15:$C$30)))*10,0)) | N29: Investments | O29: =SUMIFS('💳 Transactions'!$J$12:$J$5000,'💳 Transactions'!$E$12:$E$5000,"Investments",'💳 Transactions'!$B$12:$B$5000,">="&'🏠 Dashboard'!$C$6,'💳 Transactions'!$B$12:$B$5000,"<"&EOMONTH('🏠 Dashboard'!$C$6,0)+1)+ROW()/10000000
B30: 📦 Other | C30: =SUMIFS('💳 Transactions'!$J$12:$J$5000,'💳 Transactions'!$E$12:$E$5000,"Other",'💳 Transactions'!$B$12:$B$5000,">="&'🏠 Dashboard'!$C$6,'💳 Transactions'!$B$12:$B$5000,"<"&EOMONTH('🏠 Dashboard'!$C$6,0)+1) | D30: =IFERROR($C30/SUMIFS('💳 Transactions'!$J$12:$J$5000,'💳 Transactions'!$B$12:$B$5000,">="&'🏠 Dashboard'!$C$6,'💳 Transactions'!$B$12:$B$5000,"<"&EOMONTH('🏠 Dashboard'!$C$6,0)+1),0) | E30: =REPT("█",ROUND(MAX(0,MIN(1,$C30/MAX($C$15:$C$30)))*10,0))&REPT("░",10-ROUND(MAX(0,MIN(1,$C30/MAX($C$15:$C$30)))*10,0)) | N30: Other | O30: =SUMIFS('💳 Transactions'!$J$12:$J$5000,'💳 Transactions'!$E$12:$E$5000,"Other",'💳 Transactions'!$B$12:$B$5000,">="&'🏠 Dashboard'!$C$6,'💳 Transactions'!$B$12:$B$5000,"<"&EOMONTH('🏠 Dashboard'!$C$6,0)+1)+ROW()/10000000
B31: TOTAL | C31: =SUMIFS('💳 Transactions'!$J$12:$J$5000,'💳 Transactions'!$B$12:$B$5000,">="&'🏠 Dashboard'!$C$6,'💳 Transactions'!$B$12:$B$5000,"<"&EOMONTH('🏠 Dashboard'!$C$6,0)+1)
B33: SIX-MONTH TREND
O34: =TEXT(EDATE('🏠 Dashboard'!$C$6,-5),"mmm") | P34: =TEXT(EDATE('🏠 Dashboard'!$C$6,-4),"mmm") | Q34: =TEXT(EDATE('🏠 Dashboard'!$C$6,-3),"mmm") | R34: =TEXT(EDATE('🏠 Dashboard'!$C$6,-2),"mmm") | S34: =TEXT(EDATE('🏠 Dashboard'!$C$6,-1),"mmm") | T34: =TEXT(EDATE('🏠 Dashboard'!$C$6,0),"mmm")
N35: Income | O35: =SUMIFS('💳 Transactions'!$I$12:$I$5000,'💳 Transactions'!$B$12:$B$5000,">="&EDATE('🏠 Dashboard'!$C$6,-5),'💳 Transactions'!$B$12:$B$5000,"<"&EDATE('🏠 Dashboard'!$C$6,-4)) | P35: =SUMIFS('💳 Transactions'!$I$12:$I$5000,'💳 Transactions'!$B$12:$B$5000,">="&EDATE('🏠 Dashboard'!$C$6,-4),'💳 Transactions'!$B$12:$B$5000,"<"&EDATE('🏠 Dashboard'!$C$6,-3)) | Q35: =SUMIFS('💳 Transactions'!$I$12:$I$5000,'💳 Transactions'!$B$12:$B$5000,">="&EDATE('🏠 Dashboard'!$C$6,-3),'💳 Transactions'!$B$12:$B$5000,"<"&EDATE('🏠 Dashboard'!$C$6,-2)) | R35: =SUMIFS('💳 Transactions'!$I$12:$I$5000,'💳 Transactions'!$B$12:$B$5000,">="&EDATE('🏠 Dashboard'!$C$6,-2),'💳 Transactions'!$B$12:$B$5000,"<"&EDATE('🏠 Dashboard'!$C$6,-1)) | S35: =SUMIFS('💳 Transactions'!$I$12:$I$5000,'💳 Transactions'!$B$12:$B$5000,">="&EDATE('🏠 Dashboard'!$C$6,-1),'💳 Transactions'!$B$12:$B$5000,"<"&EDATE('🏠 Dashboard'!$C$6,0)) | T35: =SUMIFS('💳 Transactions'!$I$12:$I$5000,'💳 Transactions'!$B$12:$B$5000,">="&EDATE('🏠 Dashboard'!$C$6,0),'💳 Transactions'!$B$12:$B$5000,"<"&EDATE('🏠 Dashboard'!$C$6,1))
N36: Expenses | O36: =SUMIFS('💳 Transactions'!$J$12:$J$5000,'💳 Transactions'!$B$12:$B$5000,">="&EDATE('🏠 Dashboard'!$C$6,-5),'💳 Transactions'!$B$12:$B$5000,"<"&EDATE('🏠 Dashboard'!$C$6,-4)) | P36: =SUMIFS('💳 Transactions'!$J$12:$J$5000,'💳 Transactions'!$B$12:$B$5000,">="&EDATE('🏠 Dashboard'!$C$6,-4),'💳 Transactions'!$B$12:$B$5000,"<"&EDATE('🏠 Dashboard'!$C$6,-3)) | Q36: =SUMIFS('💳 Transactions'!$J$12:$J$5000,'💳 Transactions'!$B$12:$B$5000,">="&EDATE('🏠 Dashboard'!$C$6,-3),'💳 Transactions'!$B$12:$B$5000,"<"&EDATE('🏠 Dashboard'!$C$6,-2)) | R36: =SUMIFS('💳 Transactions'!$J$12:$J$5000,'💳 Transactions'!$B$12:$B$5000,">="&EDATE('🏠 Dashboard'!$C$6,-2),'💳 Transactions'!$B$12:$B$5000,"<"&EDATE('🏠 Dashboard'!$C$6,-1)) | S36: =SUMIFS('💳 Transactions'!$J$12:$J$5000,'💳 Transactions'!$B$12:$B$5000,">="&EDATE('🏠 Dashboard'!$C$6,-1),'💳 Transactions'!$B$12:$B$5000,"<"&EDATE('🏠 Dashboard'!$C$6,0)) | T36: =SUMIFS('💳 Transactions'!$J$12:$J$5000,'💳 Transactions'!$B$12:$B$5000,">="&EDATE('🏠 Dashboard'!$C$6,0),'💳 Transactions'!$B$12:$B$5000,"<"&EDATE('🏠 Dashboard'!$C$6,1))

Sheet 💳 Transactions
B2: 💳 Transactions
B3: The only page you type in — log it here, watch everything else update itself
B6: 💰 TOTAL INCOME | D6: 💸 TOTAL EXPENSES | F6: 💼 BALANCE
B7: =SUM(I12:I5000) | D7: =SUM(J12:J5000) | F7: =SUM(I12:I5000)-SUM(J12:J5000)
B9: ="All time" | D9: ="All time" | F9: ="Income − expenses"
B11: DATE | C11: DESCRIPTION | E11: CATEGORY | F11: SUBCATEGORY | G11: PAYMENT | H11: ACCOUNT | I11: INCOME | J11: EXPENSE | K11: NOTES
B12: 46143 | C12: Monthly salary | D12: =IF($E12="","",IFERROR(VLOOKUP($E12,CatIcons,2,FALSE),"")) | E12: Income | F12: Salary | G12: Bank Transfer | H12: Checking | I12: 2600
B13: 46143 | C13: Rent | D13: =IF($E13="","",IFERROR(VLOOKUP($E13,CatIcons,2,FALSE),"")) | E13: Housing | F13: Rent | G13: Bank Transfer | H13: Checking | J13: 850
B14: 46145 | C14: Groceries — Mercadona | D14: =IF($E14="","",IFERROR(VLOOKUP($E14,CatIcons,2,FALSE),"")) | E14: Food | F14: Groceries | G14: Card | H14: Checking | J14: 86.4
B15: 46147 | C15: Gym membership | D15: =IF($E15="","",IFERROR(VLOOKUP($E15,CatIcons,2,FALSE),"")) | E15: Health | F15: Fitness | G15: Card | H15: Checking | J15: 29.9
B16: 46149 | C16: Freelance project | D16: =IF($E16="","",IFERROR(VLOOKUP($E16,CatIcons,2,FALSE),"")) | E16: Income | F16: Freelance | G16: PayPal | H16: Checking | I16: 420
B17: 46150 | C17: Gas | D17: =IF($E17="","",IFERROR(VLOOKUP($E17,CatIcons,2,FALSE),"")) | E17: Transportation | F17: Fuel | G17: Card | H17: Credit Card | J17: 52
B18: 46152 | C18: Netflix | D18: =IF($E18="","",IFERROR(VLOOKUP($E18,CatIcons,2,FALSE),"")) | E18: Subscriptions | F18: Streaming | G18: Card | H18: Credit Card | J18: 12.99
B19: 46154 | C19: Dinner out | D19: =IF($E19="","",IFERROR(VLOOKUP($E19,CatIcons,2,FALSE),"")) | E19: Food | F19: Restaurants | G19: Card | H19: Credit Card | J19: 43.5
B20: 46157 | C20: Transfer to savings | D20: =IF($E20="","",IFERROR(VLOOKUP($E20,CatIcons,2,FALSE),"")) | E20: Savings | F20: Emergency Fund | G20: Bank Transfer | H20: Savings | J20: 300
B21: 46160 | C21: New sneakers | D21: =IF($E21="","",IFERROR(VLOOKUP($E21,CatIcons,2,FALSE),"")) | E21: Shopping | F21: Clothing | G21: Card | H21: Credit Card | J21: 74.99
B22: 46162 | C22: Electricity bill | D22: =IF($E22="","",IFERROR(VLOOKUP($E22,CatIcons,2,FALSE),"")) | E22: Housing | F22: Utilities | G22: Bank Transfer | H22: Checking | J22: 64.2
B23: 46164 | C23: Pharmacy | D23: =IF($E23="","",IFERROR(VLOOKUP($E23,CatIcons,2,FALSE),"")) | E23: Health | F23: Medicine | G23: Cash | H23: Cash | J23: 18.35
B24: 46167 | C24: Index fund | D24: =IF($E24="","",IFERROR(VLOOKUP($E24,CatIcons,2,FALSE),"")) | E24: Investments | F24: Index Funds | G24: Bank Transfer | H24: Checking | J24: 200
B25: 46170 | C25: Groceries | D25: =IF($E25="","",IFERROR(VLOOKUP($E25,CatIcons,2,FALSE),"")) | E25: Food | F25: Groceries | G25: Card | H25: Checking | J25: 92.1
B26: 46174 | C26: Monthly salary | D26: =IF($E26="","",IFERROR(VLOOKUP($E26,CatIcons,2,FALSE),"")) | E26: Income | F26: Salary | G26: Bank Transfer | H26: Checking | I26: 2600
B27: 46174 | C27: Rent | D27: =IF($E27="","",IFERROR(VLOOKUP($E27,CatIcons,2,FALSE),"")) | E27: Housing | F27: Rent | G27: Bank Transfer | H27: Checking | J27: 850
B28: 46175 | C28: Groceries | D28: =IF($E28="","",IFERROR(VLOOKUP($E28,CatIcons,2,FALSE),"")) | E28: Food | F28: Groceries | G28: Card | H28: Checking | J28: 81.75
B29: 46177 | C29: Spotify | D29: =IF($E29="","",IFERROR(VLOOKUP($E29,CatIcons,2,FALSE),"")) | E29: Subscriptions | F29: Music | G29: Card | H29: Credit Card | J29: 10.99
B30: 46179 | C30: Freelance project | D30: =IF($E30="","",IFERROR(VLOOKUP($E30,CatIcons,2,FALSE),"")) | E30: Income | F30: Freelance | G30: PayPal | H30: Checking | I30: 380
B31: 46181 | C31: Bus pass | D31: =IF($E31="","",IFERROR(VLOOKUP($E31,CatIcons,2,FALSE),"")) | E31: Transportation | F31: Public Transit | G31: Card | H31: Checking | J31: 40
B32: 46183 | C32: Cinema | D32: =IF($E32="","",IFERROR(VLOOKUP($E32,CatIcons,2,FALSE),"")) | E32: Entertainment | F32: Movies | G32: Card | H32: Credit Card | J32: 22
B33: 46185 | C33: Groceries | D33: =IF($E33="","",IFERROR(VLOOKUP($E33,CatIcons,2,FALSE),"")) | E33: Food | F33: Groceries | G33: Card | H33: Checking | J33: 88.6
B34: 46188 | C34: Transfer to savings | D34: =IF($E34="","",IFERROR(VLOOKUP($E34,CatIcons,2,FALSE),"")) | E34: Savings | F34: Emergency Fund | G34: Bank Transfer | H34: Savings | J34: 300
B35: 46190 | C35: Car insurance | D35: =IF($E35="","",IFERROR(VLOOKUP($E35,CatIcons,2,FALSE),"")) | E35: Insurance | F35: Auto | G35: Bank Transfer | H35: Checking | J35: 58
B36: 46193 | C36: Birthday gift | D36: =IF($E36="","",IFERROR(VLOOKUP($E36,CatIcons,2,FALSE),"")) | E36: Shopping | F36: Gifts | G36: Card | H36: Credit Card | J36: 35
B37: 46195 | C37: Online course | D37: =IF($E37="","",IFERROR(VLOOKUP($E37,CatIcons,2,FALSE),"")) | E37: Education | F37: Courses | G37: Card | H37: Checking | J37: 49
B38: 46198 | C38: Index fund | D38: =IF($E38="","",IFERROR(VLOOKUP($E38,CatIcons,2,FALSE),"")) | E38: Investments | F38: Index Funds | G38: Bank Transfer | H38: Checking | J38: 200
B39: 46200 | C39: Weekend trip fuel | D39: =IF($E39="","",IFERROR(VLOOKUP($E39,CatIcons,2,FALSE),"")) | E39: Travel | F39: Road Trip | G39: Card | H39: Credit Card | J39: 45.3
B40: 46204 | C40: Monthly salary | D40: =IF($E40="","",IFERROR(VLOOKUP($E40,CatIcons,2,FALSE),"")) | E40: Income | F40: Salary | G40: Bank Transfer | H40: Checking | I40: 2600
B41: 46204 | C41: Rent | D41: =IF($E41="","",IFERROR(VLOOKUP($E41,CatIcons,2,FALSE),"")) | E41: Housing | F41: Rent | G41: Bank Transfer | H41: Checking | J41: 850
B42: 46205 | C42: Groceries | D42: =IF($E42="","",IFERROR(VLOOKUP($E42,CatIcons,2,FALSE),"")) | E42: Food | F42: Groceries | G42: Card | H42: Checking | J42: 79.4
B43: 46206 | C43: Refund — returned item | D43: =IF($E43="","",IFERROR(VLOOKUP($E43,CatIcons,2,FALSE),"")) | E43: Income | F43: Refunds | G43: Card | H43: Checking | I43: 24.99
B44: 46207 | C44: Gas | D44: =IF($E44="","",IFERROR(VLOOKUP($E44,CatIcons,2,FALSE),"")) | E44: Transportation | F44: Fuel | G44: Card | H44: Credit Card | J44: 50
B45: 46208 | C45: Brunch | D45: =IF($E45="","",IFERROR(VLOOKUP($E45,CatIcons,2,FALSE),"")) | E45: Food | F45: Restaurants | G45: Card | H45: Credit Card | J45: 28.5
...

Sheet 📊 Budget
B2: 📊 Budget
B3: Set a plan in the beige cells — actuals follow the month picked on the Dashboard
B6: 🎯 PLANNED | D6: 💸 SPENT | F6: 💼 LEFT TO SPEND
B7: =SUM(C13:C28) | D7: =SUM(D13:D28) | F7: =SUM(C13:C28)-SUM(D13:D28)
B9: ="Total monthly budget" | D9: =TEXT('🏠 Dashboard'!$C$6,"mmmm yyyy") | F9: ="Planned − spent"
B12: CATEGORY | C12: BUDGET | D12: ACTUAL | E12: LEFT | F12: % USED | H12: STATUS
B13: 🏠 Housing | C13: 950 | D13: =SUMIFS('💳 Transactions'!$J$12:$J$5000,'💳 Transactions'!$E$12:$E$5000,"Housing",'💳 Transactions'!$B$12:$B$5000,">="&'🏠 Dashboard'!$C$6,'💳 Transactions'!$B$12:$B$5000,"<"&EOMONTH('🏠 Dashboard'!$C$6,0)+1) | E13: =$C13-$D13 | F13: =IFERROR($D13/$C13,0) | G13: =REPT("█",ROUND(MAX(0,MIN(1,IFERROR($D13/$C13,0)))*10,0))&REPT("░",10-ROUND(MAX(0,MIN(1,IFERROR($D13/$C13,0)))*10,0)) | H13: =IF($C13=0,"—",IF($D13>$C13,"🔴 Over",IF($D13>0.85*$C13,"🟡 Close","🟢 On track")))
B14: 🍽️ Food | C14: 350 | D14: =SUMIFS('💳 Transactions'!$J$12:$J$5000,'💳 Transactions'!$E$12:$E$5000,"Food",'💳 Transactions'!$B$12:$B$5000,">="&'🏠 Dashboard'!$C$6,'💳 Transactions'!$B$12:$B$5000,"<"&EOMONTH('🏠 Dashboard'!$C$6,0)+1) | E14: =$C14-$D14 | F14: =IFERROR($D14/$C14,0) | G14: =REPT("█",ROUND(MAX(0,MIN(1,IFERROR($D14/$C14,0)))*10,0))&REPT("░",10-ROUND(MAX(0,MIN(1,IFERROR($D14/$C14,0)))*10,0)) | H14: =IF($C14=0,"—",IF($D14>$C14,"🔴 Over",IF($D14>0.85*$C14,"🟡 Close","🟢 On track")))
B15: 🚗 Transportation | C15: 120 | D15: =SUMIFS('💳 Transactions'!$J$12:$J$5000,'💳 Transactions'!$E$12:$E$5000,"Transportation",'💳 Transactions'!$B$12:$B$5000,">="&'🏠 Dashboard'!$C$6,'💳 Transactions'!$B$12:$B$5000,"<"&EOMONTH('🏠 Dashboard'!$C$6,0)+1) | E15: =$C15-$D15 | F15: =IFERROR($D15/$C15,0) | G15: =REPT("█",ROUND(MAX(0,MIN(1,IFERROR($D15/$C15,0)))*10,0))&REPT("░",10-ROUND(MAX(0,MIN(1,IFERROR($D15/$C15,0)))*10,0)) | H15: =IF($C15=0,"—",IF($D15>$C15,"🔴 Over",IF($D15>0.85*$C15,"🟡 Close","🟢 On track")))
B16: 🛍️ Shopping | C16: 100 | D16: =SUMIFS('💳 Transactions'!$J$12:$J$5000,'💳 Transactions'!$E$12:$E$5000,"Shopping",'💳 Transactions'!$B$12:$B$5000,">="&'🏠 Dashboard'!$C$6,'💳 Transactions'!$B$12:$B$5000,"<"&EOMONTH('🏠 Dashboard'!$C$6,0)+1) | E16: =$C16-$D16 | F16: =IFERROR($D16/$C16,0) | G16: =REPT("█",ROUND(MAX(0,MIN(1,IFERROR($D16/$C16,0)))*10,0))&REPT("░",10-ROUND(MAX(0,MIN(1,IFERROR($D16/$C16,0)))*10,0)) | H16: =IF($C16=0,"—",IF($D16>$C16,"🔴 Over",IF($D16>0.85*$C16,"🟡 Close","🟢 On track")))
B17: 🎬 Entertainment | C17: 60 | D17: =SUMIFS('💳 Transactions'!$J$12:$J$5000,'💳 Transactions'!$E$12:$E$5000,"Entertainment",'💳 Transactions'!$B$12:$B$5000,">="&'🏠 Dashboard'!$C$6,'💳 Transactions'!$B$12:$B$5000,"<"&EOMONTH('🏠 Dashboard'!$C$6,0)+1) | E17: =$C17-$D17 | F17: =IFERROR($D17/$C17,0) | G17: =REPT("█",ROUND(MAX(0,MIN(1,IFERROR($D17/$C17,0)))*10,0))&REPT("░",10-ROUND(MAX(0,MIN(1,IFERROR($D17/$C17,0)))*10,0)) | H17: =IF($C17=0,"—",IF($D17>$C17,"🔴 Over",IF($D17>0.85*$C17,"🟡 Close","🟢 On track")))
B18: 🩺 Health | C18: 80 | D18: =SUMIFS('💳 Transactions'!$J$12:$J$5000,'💳 Transactions'!$E$12:$E$5000,"Health",'💳 Transactions'!$B$12:$B$5000,">="&'🏠 Dashboard'!$C$6,'💳 Transactions'!$B$12:$B$5000,"<"&EOMONTH('🏠 Dashboard'!$C$6,0)+1) | E18: =$C18-$D18 | F18: =IFERROR($D18/$C18,0) | G18: =REPT("█",ROUND(MAX(0,MIN(1,IFERROR($D18/$C18,0)))*10,0))&REPT("░",10-ROUND(MAX(0,MIN(1,IFERROR($D18/$C18,0)))*10,0)) | H18: =IF($C18=0,"—",IF($D18>$C18,"🔴 Over",IF($D18>0.85*$C18,"🟡 Close","🟢 On track")))
B19: 🛡️ Insurance | C19: 60 | D19: =SUMIFS('💳 Transactions'!$J$12:$J$5000,'💳 Transactions'!$E$12:$E$5000,"Insurance",'💳 Transactions'!$B$12:$B$5000,">="&'🏠 Dashboard'!$C$6,'💳 Transactions'!$B$12:$B$5000,"<"&EOMONTH('🏠 Dashboard'!$C$6,0)+1) | E19: =$C19-$D19 | F19: =IFERROR($D19/$C19,0) | G19: =REPT("█",ROUND(MAX(0,MIN(1,IFERROR($D19/$C19,0)))*10,0))&REPT("░",10-ROUND(MAX(0,MIN(1,IFERROR($D19/$C19,0)))*10,0)) | H19: =IF($C19=0,"—",IF($D19>$C19,"🔴 Over",IF($D19>0.85*$C19,"🟡 Close","🟢 On track")))
B20: ✈️ Travel | C20: 80 | D20: =SUMIFS('💳 Transactions'!$J$12:$J$5000,'💳 Transactions'!$E$12:$E$5000,"Travel",'💳 Transactions'!$B$12:$B$5000,">="&'🏠 Dashboard'!$C$6,'💳 Transactions'!$B$12:$B$5000,"<"&EOMONTH('🏠 Dashboard'!$C$6,0)+1) | E20: =$C20-$D20 | F20: =IFERROR($D20/$C20,0) | G20: =REPT("█",ROUND(MAX(0,MIN(1,IFERROR($D20/$C20,0)))*10,0))&REPT("░",10-ROUND(MAX(0,MIN(1,IFERROR($D20/$C20,0)))*10,0)) | H20: =IF($C20=0,"—",IF($D20>$C20,"🔴 Over",IF($D20>0.85*$C20,"🟡 Close","🟢 On track")))
B21: 🎓 Education | C21: 50 | D21: =SUMIFS('💳 Transactions'!$J$12:$J$5000,'💳 Transactions'!$E$12:$E$5000,"Education",'💳 Transactions'!$B$12:$B$5000,">="&'🏠 Dashboard'!$C$6,'💳 Transactions'!$B$12:$B$5000,"<"&EOMONTH('🏠 Dashboard'!$C$6,0)+1) | E21: =$C21-$D21 | F21: =IFERROR($D21/$C21,0) | G21: =REPT("█",ROUND(MAX(0,MIN(1,IFERROR($D21/$C21,0)))*10,0))&REPT("░",10-ROUND(MAX(0,MIN(1,IFERROR($D21/$C21,0)))*10,0)) | H21: =IF($C21=0,"—",IF($D21>$C21,"🔴 Over",IF($D21>0.85*$C21,"🟡 Close","🟢 On track")))
B22: 🔁 Subscriptions | C22: 30 | D22: =SUMIFS('💳 Transactions'!$J$12:$J$5000,'💳 Transactions'!$E$12:$E$5000,"Subscriptions",'💳 Transactions'!$B$12:$B$5000,">="&'🏠 Dashboard'!$C$6,'💳 Transactions'!$B$12:$B$5000,"<"&EOMONTH('🏠 Dashboard'!$C$6,0)+1) | E22: =$C22-$D22 | F22: =IFERROR($D22/$C22,0) | G22: =REPT("█",ROUND(MAX(0,MIN(1,IFERROR($D22/$C22,0)))*10,0))&REPT("░",10-ROUND(MAX(0,MIN(1,IFERROR($D22/$C22,0)))*10,0)) | H22: =IF($C22=0,"—",IF($D22>$C22,"🔴 Over",IF($D22>0.85*$C22,"🟡 Close","🟢 On track")))
B23: 🐾 Pets | C23: 0 | D23: =SUMIFS('💳 Transactions'!$J$12:$J$5000,'💳 Transactions'!$E$12:$E$5000,"Pets",'💳 Transactions'!$B$12:$B$5000,">="&'🏠 Dashboard'!$C$6,'💳 Transactions'!$B$12:$B$5000,"<"&EOMONTH('🏠 Dashboard'!$C$6,0)+1) | E23: =$C23-$D23 | F23: =IFERROR($D23/$C23,0) | G23: =REPT("█",ROUND(MAX(0,MIN(1,IFERROR($D23/$C23,0)))*10,0))&REPT("░",10-ROUND(MAX(0,MIN(1,IFERROR($D23/$C23,0)))*10,0)) | H23: =IF($C23=0,"—",IF($D23>$C23,"🔴 Over",IF($D23>0.85*$C23,"🟡 Close","🟢 On track")))
B24: 🧸 Children | C24: 0 | D24: =SUMIFS('💳 Transactions'!$J$12:$J$5000,'💳 Transactions'!$E$12:$E$5000,"Children",'💳 Transactions'!$B$12:$B$5000,">="&'🏠 Dashboard'!$C$6,'💳 Transactions'!$B$12:$B$5000,"<"&EOMONTH('🏠 Dashboard'!$C$6,0)+1) | E24: =$C24-$D24 | F24: =IFERROR($D24/$C24,0) | G24: =REPT("█",ROUND(MAX(0,MIN(1,IFERROR($D24/$C24,0)))*10,0))&REPT("░",10-ROUND(MAX(0,MIN(1,IFERROR($D24/$C24,0)))*10,0)) | H24: =IF($C24=0,"—",IF($D24>$C24,"🔴 Over",IF($D24>0.85*$C24,"🟡 Close","🟢 On track")))
B25: 🏛️ Taxes | C25: 0 | D25: =SUMIFS('💳 Transactions'!$J$12:$J$5000,'💳 Transactions'!$E$12:$E$5000,"Taxes",'💳 Transactions'!$B$12:$B$5000,">="&'🏠 Dashboard'!$C$6,'💳 Transactions'!$B$12:$B$5000,"<"&EOMONTH('🏠 Dashboard'!$C$6,0)+1) | E25: =$C25-$D25 | F25: =IFERROR($D25/$C25,0) | G25: =REPT("█",ROUND(MAX(0,MIN(1,IFERROR($D25/$C25,0)))*10,0))&REPT("░",10-ROUND(MAX(0,MIN(1,IFERROR($D25/$C25,0)))*10,0)) | H25: =IF($C25=0,"—",IF($D25>$C25,"🔴 Over",IF($D25>0.85*$C25,"🟡 Close","🟢 On track")))
B26: 🌱 Savings | C26: 300 | D26: =SUMIFS('💳 Transactions'!$J$12:$J$5000,'💳 Transactions'!$E$12:$E$5000,"Savings",'💳 Transactions'!$B$12:$B$5000,">="&'🏠 Dashboard'!$C$6,'💳 Transactions'!$B$12:$B$5000,"<"&EOMONTH('🏠 Dashboard'!$C$6,0)+1) | E26: =$C26-$D26 | F26: =IFERROR($D26/$C26,0) | G26: =REPT("█",ROUND(MAX(0,MIN(1,IFERROR($D26/$C26,0)))*10,0))&REPT("░",10-ROUND(MAX(0,MIN(1,IFERROR($D26/$C26,0)))*10,0)) | H26: =IF($C26=0,"—",IF($D26>$C26,"🔴 Over",IF($D26>0.85*$C26,"🟡 Close","🟢 On track")))
B27: 📈 Investments | C27: 200 | D27: =SUMIFS('💳 Transactions'!$J$12:$J$5000,'💳 Transactions'!$E$12:$E$5000,"Investments",'💳 Transactions'!$B$12:$B$5000,">="&'🏠 Dashboard'!$C$6,'💳 Transactions'!$B$12:$B$5000,"<"&EOMONTH('🏠 Dashboard'!$C$6,0)+1) | E27: =$C27-$D27 | F27: =IFERROR($D27/$C27,0) | G27: =REPT("█",ROUND(MAX(0,MIN(1,IFERROR($D27/$C27,0)))*10,0))&REPT("░",10-ROUND(MAX(0,MIN(1,IFERROR($D27/$C27,0)))*10,0)) | H27: =IF($C27=0,"—",IF($D27>$C27,"🔴 Over",IF($D27>0.85*$C27,"🟡 Close","🟢 On track")))
B28: 📦 Other | C28: 50 | D28: =SUMIFS('💳 Transactions'!$J$12:$J$5000,'💳 Transactions'!$E$12:$E$5000,"Other",'💳 Transactions'!$B$12:$B$5000,">="&'🏠 Dashboard'!$C$6,'💳 Transactions'!$B$12:$B$5000,"<"&EOMONTH('🏠 Dashboard'!$C$6,0)+1) | E28: =$C28-$D28 | F28: =IFERROR($D28/$C28,0) | G28: =REPT("█",ROUND(MAX(0,MIN(1,IFERROR($D28/$C28,0)))*10,0))&REPT("░",10-ROUND(MAX(0,MIN(1,IFERROR($D28/$C28,0)))*10,0)) | H28: =IF($C28=0,"—",IF($D28>$C28,"🔴 Over",IF($D28>0.85*$C28,"🟡 Close","🟢 On track")))
B29: TOTAL | C29: =SUM(C13:C28) | D29: =SUM(D13:D28) | E29: =C29-D29

Sheet 🌱 Goals
B2: 🌱 Goals
B3: Name it, price it, date it — the planner tells you what to put away each month
B6: 🎯 TOTAL TARGET | D6: 🌱 SAVED SO FAR | F6: 🚀 OVERALL PROGRESS
B7: =SUM(C13:C20) | D7: =SUM(D13:D20) | F7: =IFERROR(SUM(D13:D20)/SUM(C13:C20),0)
B12: GOAL | C12: TARGET | D12: SAVED | E12: TARGET DATE | F12: MONTHS LEFT | G12: NEEDED / MO | I12: %
B13: 🛟 Emergency fund | C13: 5000 | D13: 2100 | E13: 46387 | F13: =IF($E13="","",MAX(1,DATEDIF(TODAY(),$E13,"m"))) | G13: =IF($B13="","",MAX(0,$C13-$D13)/IF($F13="",1,$F13)) | H13: =IF($B13="","",REPT("█",ROUND(MAX(0,MIN(1,IFERROR($D13/$C13,0)))*10,0))&REPT("░",10-ROUND(MAX(0,MIN(1,IFERROR($D13/$C13,0)))*10,0))) | I13: =IF($B13="","",IFERROR($D13/$C13,0))
B14: ✈️ Summer trip | C14: 1200 | D14: 450 | E14: 46539 | F14: =IF($E14="","",MAX(1,DATEDIF(TODAY(),$E14,"m"))) | G14: =IF($B14="","",MAX(0,$C14-$D14)/IF($F14="",1,$F14)) | H14: =IF($B14="","",REPT("█",ROUND(MAX(0,MIN(1,IFERROR($D14/$C14,0)))*10,0))&REPT("░",10-ROUND(MAX(0,MIN(1,IFERROR($D14/$C14,0)))*10,0))) | I14: =IF($B14="","",IFERROR($D14/$C14,0))
B15: 💻 New laptop | C15: 1500 | D15: 600 | E15: 46327 | F15: =IF($E15="","",MAX(1,DATEDIF(TODAY(),$E15,"m"))) | G15: =IF($B15="","",MAX(0,$C15-$D15)/IF($F15="",1,$F15)) | H15: =IF($B15="","",REPT("█",ROUND(MAX(0,MIN(1,IFERROR($D15/$C15,0)))*10,0))&REPT("░",10-ROUND(MAX(0,MIN(1,IFERROR($D15/$C15,0)))*10,0))) | I15: =IF($B15="","",IFERROR($D15/$C15,0))
F16: =IF($E16="","",MAX(1,DATEDIF(TODAY(),$E16,"m"))) | G16: =IF($B16="","",MAX(0,$C16-$D16)/IF($F16="",1,$F16)) | H16: =IF($B16="","",REPT("█",ROUND(MAX(0,MIN(1,IFERROR($D16/$C16,0)))*10,0))&REPT("░",10-ROUND(MAX(0,MIN(1,IFERROR($D16/$C16,0)))*10,0))) | I16: =IF($B16="","",IFERROR($D16/$C16,0))
F17: =IF($E17="","",MAX(1,DATEDIF(TODAY(),$E17,"m"))) | G17: =IF($B17="","",MAX(0,$C17-$D17)/IF($F17="",1,$F17)) | H17: =IF($B17="","",REPT("█",ROUND(MAX(0,MIN(1,IFERROR($D17/$C17,0)))*10,0))&REPT("░",10-ROUND(MAX(0,MIN(1,IFERROR($D17/$C17,0)))*10,0))) | I17: =IF($B17="","",IFERROR($D17/$C17,0))
F18: =IF($E18="","",MAX(1,DATEDIF(TODAY(),$E18,"m"))) | G18: =IF($B18="","",MAX(0,$C18-$D18)/IF($F18="",1,$F18)) | H18: =IF($B18="","",REPT("█",ROUND(MAX(0,MIN(1,IFERROR($D18/$C18,0)))*10,0))&REPT("░",10-ROUND(MAX(0,MIN(1,IFERROR($D18/$C18,0)))*10,0))) | I18: =IF($B18="","",IFERROR($D18/$C18,0))
F19: =IF($E19="","",MAX(1,DATEDIF(TODAY(),$E19,"m"))) | G19: =IF($B19="","",MAX(0,$C19-$D19)/IF($F19="",1,$F19)) | H19: =IF($B19="","",REPT("█",ROUND(MAX(0,MIN(1,IFERROR($D19/$C19,0)))*10,0))&REPT("░",10-ROUND(MAX(0,MIN(1,IFERROR($D19/$C19,0)))*10,0))) | I19: =IF($B19="","",IFERROR($D19/$C19,0))
F20: =IF($E20="","",MAX(1,DATEDIF(TODAY(),$E20,"m"))) | G20: =IF($B20="","",MAX(0,$C20-$D20)/IF($F20="",1,$F20)) | H20: =IF($B20="","",REPT("█",ROUND(MAX(0,MIN(1,IFERROR($D20/$C20,0)))*10,0))&REPT("░",10-ROUND(MAX(0,MIN(1,IFERROR($D20/$C20,0)))*10,0))) | I20: =IF($B20="","",IFERROR($D20/$C20,0))
B22: 💡 Log 'Transfer to savings' rows on the Transactions page, then update SAVED here.

Sheet 📅 Year
B2: 📅 Year at a Glance
B3: Every category, every month — darker cells mean heavier spending
B6: YEAR | C6: 2026
B8: CATEGORY | C8: JAN | D8: FEB | E8: MAR | F8: APR | G8: MAY | H8: JUN | I8: JUL | J8: AUG | K8: SEP | L8: OCT | M8: NOV | N8: DEC | O8: TOTAL
B9: 🏠 Housing | C9: =SUMIFS('💳 Transactions'!$J$12:$J$5000,'💳 Transactions'!$E$12:$E$5000,"Housing",'💳 Transactions'!$B$12:$B$5000,">="&DATE('📅 Year'!$C$6,1,1),'💳 Transactions'!$B$12:$B$5000,"<"&DATE('📅 Year'!$C$6,1+1,1)) | D9: =SUMIFS('💳 Transactions'!$J$12:$J$5000,'💳 Transactions'!$E$12:$E$5000,"Housing",'💳 Transactions'!$B$12:$B$5000,">="&DATE('📅 Year'!$C$6,2,1),'💳 Transactions'!$B$12:$B$5000,"<"&DATE('📅 Year'!$C$6,2+1,1)) | E9: =SUMIFS('💳 Transactions'!$J$12:$J$5000,'💳 Transactions'!$E$12:$E$5000,"Housing",'💳 Transactions'!$B$12:$B$5000,">="&DATE('📅 Year'!$C$6,3,1),'💳 Transactions'!$B$12:$B$5000,"<"&DATE('📅 Year'!$C$6,3+1,1)) | F9: =SUMIFS('💳 Transactions'!$J$12:$J$5000,'💳 Transactions'!$E$12:$E$5000,"Housing",'💳 Transactions'!$B$12:$B$5000,">="&DATE('📅 Year'!$C$6,4,1),'💳 Transactions'!$B$12:$B$5000,"<"&DATE('📅 Year'!$C$6,4+1,1)) | G9: =SUMIFS('💳 Transactions'!$J$12:$J$5000,'💳 Transactions'!$E$12:$E$5000,"Housing",'💳 Transactions'!$B$12:$B$5000,">="&DATE('📅 Year'!$C$6,5,1),'💳 Transactions'!$B$12:$B$5000,"<"&DATE('📅 Year'!$C$6,5+1,1)) | H9: =SUMIFS('💳 Transactions'!$J$12:$J$5000,'💳 Transactions'!$E$12:$E$5000,"Housing",'💳 Transactions'!$B$12:$B$5000,">="&DATE('📅 Year'!$C$6,6,1),'💳 Transactions'!$B$12:$B$5000,"<"&DATE('📅 Year'!$C$6,6+1,1)) | I9: =SUMIFS('💳 Transactions'!$J$12:$J$5000,'💳 Transactions'!$E$12:$E$5000,"Housing",'💳 Transactions'!$B$12:$B$5000,">="&DATE('📅 Year'!$C$6,7,1),'💳 Transactions'!$B$12:$B$5000,"<"&DATE('📅 Year'!$C$6,7+1,1)) | J9: =SUMIFS('💳 Transactions'!$J$12:$J$5000,'💳 Transactions'!$E$12:$E$5000,"Housing",'💳 Transactions'!$B$12:$B$5000,">="&DATE('📅 Year'!$C$6,8,1),'💳 Transactions'!$B$12:$B$5000,"<"&DATE('📅 Year'!$C$6,8+1,1)) | K9: =SUMIFS('💳 Transactions'!$J$12:$J$5000,'💳 Transactions'!$E$12:$E$5000,"Housing",'💳 Transactions'!$B$12:$B$5000,">="&DATE('📅 Year'!$C$6,9,1),'💳 Transactions'!$B$12:$B$5000,"<"&DATE('📅 Year'!$C$6,9+1,1)) | L9: =SUMIFS('💳 Transactions'!$J$12:$J$5000,'💳 Transactions'!$E$12:$E$5000,"Housing",'💳 Transactions'!$B$12:$B$5000,">="&DATE('📅 Year'!$C$6,10,1),'💳 Transactions'!$B$12:$B$5000,"<"&DATE('📅 Year'!$C$6,10+1,1)) | M9: =SUMIFS('💳 Transactions'!$J$12:$J$5000,'💳 Transactions'!$E$12:$E$5000,"Housing",'💳 Transactions'!$B$12:$B$5000,">="&DATE('📅 Year'!$C$6,11,1),'💳 Transactions'!$B$12:$B$5000,"<"&DATE('📅 Year'!$C$6,11+1,1)) | N9: =SUMIFS('💳 Transactions'!$J$12:$J$5000,'💳 Transactions'!$E$12:$E$5000,"Housing",'💳 Transactions'!$B$12:$B$5000,">="&DATE('📅 Year'!$C$6,12,1),'💳 Transactions'!$B$12:$B$5000,"<"&DATE('📅 Year'!$C$6,12+1,1)) | O9: =SUM(C9:N9)
B10: 🍽️ Food | C10: =SUMIFS('💳 Transactions'!$J$12:$J$5000,'💳 Transactions'!$E$12:$E$5000,"Food",'💳 Transactions'!$B$12:$B$5000,">="&DATE('📅 Year'!$C$6,1,1),'💳 Transactions'!$B$12:$B$5000,"<"&DATE('📅 Year'!$C$6,1+1,1)) | D10: =SUMIFS('💳 Transactions'!$J$12:$J$5000,'💳 Transactions'!$E$12:$E$5000,"Food",'💳 Transactions'!$B$12:$B$5000,">="&DATE('📅 Year'!$C$6,2,1),'💳 Transactions'!$B$12:$B$5000,"<"&DATE('📅 Year'!$C$6,2+1,1)) | E10: =SUMIFS('💳 Transactions'!$J$12:$J$5000,'💳 Transactions'!$E$12:$E$5000,"Food",'💳 Transactions'!$B$12:$B$5000,">="&DATE('📅 Year'!$C$6,3,1),'💳 Transactions'!$B$12:$B$5000,"<"&DATE('📅 Year'!$C$6,3+1,1)) | F10: =SUMIFS('💳 Transactions'!$J$12:$J$5000,'💳 Transactions'!$E$12:$E$5000,"Food",'💳 Transactions'!$B$12:$B$5000,">="&DATE('📅 Year'!$C$6,4,1),'💳 Transactions'!$B$12:$B$5000,"<"&DATE('📅 Year'!$C$6,4+1,1)) | G10: =SUMIFS('💳 Transactions'!$J$12:$J$5000,'💳 Transactions'!$E$12:$E$5000,"Food",'💳 Transactions'!$B$12:$B$5000,">="&DATE('📅 Year'!$C$6,5,1),'💳 Transactions'!$B$12:$B$5000,"<"&DATE('📅 Year'!$C$6,5+1,1)) | H10: =SUMIFS('💳 Transactions'!$J$12:$J$5000,'💳 Transactions'!$E$12:$E$5000,"Food",'💳 Transactions'!$B$12:$B$5000,">="&DATE('📅 Year'!$C$6,6,1),'💳 Transactions'!$B$12:$B$5000,"<"&DATE('📅 Year'!$C$6,6+1,1)) | I10: =SUMIFS('💳 Transactions'!$J$12:$J$5000,'💳 Transactions'!$E$12:$E$5000,"Food",'💳 Transactions'!$B$12:$B$5000,">="&DATE('📅 Year'!$C$6,7,1),'💳 Transactions'!$B$12:$B$5000,"<"&DATE('📅 Year'!$C$6,7+1,1)) | J10: =SUMIFS('💳 Transactions'!$J$12:$J$5000,'💳 Transactions'!$E$12:$E$5000,"Food",'💳 Transactions'!$B$12:$B$5000,">="&DATE('📅 Year'!$C$6,8,1),'💳 Transactions'!$B$12:$B$5000,"<"&DATE('📅 Year'!$C$6,8+1,1)) | K10: =SUMIFS('💳 Transactions'!$J$12:$J$5000,'💳 Transactions'!$E$12:$E$5000,"Food",'💳 Transactions'!$B$12:$B$5000,">="&DATE('📅 Year'!$C$6,9,1),'💳 Transactions'!$B$12:$B$5000,"<"&DATE('📅 Year'!$C$6,9+1,1)) | L10: =SUMIFS('💳 Transactions'!$J$12:$J$5000,'💳 Transactions'!$E$12:$E$5000,"Food",'💳 Transactions'!$B$12:$B$5000,">="&DATE('📅 Year'!$C$6,10,1),'💳 Transactions'!$B$12:$B$5000,"<"&DATE('📅 Year'!$C$6,10+1,1)) | M10: =SUMIFS('💳 Transactions'!$J$12:$J$5000,'💳 Transactions'!$E$12:$E$5000,"Food",'💳 Transactions'!$B$12:$B$5000,">="&DATE('📅 Year'!$C$6,11,1),'💳 Transactions'!$B$12:$B$5000,"<"&DATE('📅 Year'!$C$6,11+1,1)) | N10: =SUMIFS('💳 Transactions'!$J$12:$J$5000,'💳 Transactions'!$E$12:$E$5000,"Food",'💳 Transactions'!$B$12:$B$5000,">="&DATE('📅 Year'!$C$6,12,1),'💳 Transactions'!$B$12:$B$5000,"<"&DATE('📅 Year'!$C$6,12+1,1)) | O10: =SUM(C10:N10)
B11: 🚗 Transportation | C11: =SUMIFS('💳 Transactions'!$J$12:$J$5000,'💳 Transactions'!$E$12:$E$5000,"Transportation",'💳 Transactions'!$B$12:$B$5000,">="&DATE('📅 Year'!$C$6,1,1),'💳 Transactions'!$B$12:$B$5000,"<"&DATE('📅 Year'!$C$6,1+1,1)) | D11: =SUMIFS('💳 Transactions'!$J$12:$J$5000,'💳 Transactions'!$E$12:$E$5000,"Transportation",'💳 Transactions'!$B$12:$B$5000,">="&DATE('📅 Year'!$C$6,2,1),'💳 Transactions'!$B$12:$B$5000,"<"&DATE('📅 Year'!$C$6,2+1,1)) | E11: =SUMIFS('💳 Transactions'!$J$12:$J$5000,'💳 Transactions'!$E$12:$E$5000,"Transportation",'💳 Transactions'!$B$12:$B$5000,">="&DATE('📅 Year'!$C$6,3,1),'💳 Transactions'!$B$12:$B$5000,"<"&DATE('📅 Year'!$C$6,3+1,1)) | F11: =SUMIFS('💳 Transactions'!$J$12:$J$5000,'💳 Transactions'!$E$12:$E$5000,"Transportation",'💳 Transactions'!$B$12:$B$5000,">="&DATE('📅 Year'!$C$6,4,1),'💳 Transactions'!$B$12:$B$5000,"<"&DATE('📅 Year'!$C$6,4+1,1)) | G11: =SUMIFS('💳 Transactions'!$J$12:$J$5000,'💳 Transactions'!$E$12:$E$5000,"Transportation",'💳 Transactions'!$B$12:$B$5000,">="&DATE('📅 Year'!$C$6,5,1),'💳 Transactions'!$B$12:$B$5000,"<"&DATE('📅 Year'!$C$6,5+1,1)) | H11: =SUMIFS('💳 Transactions'!$J$12:$J$5000,'💳 Transactions'!$E$12:$E$5000,"Transportation",'💳 Transactions'!$B$12:$B$5000,">="&DATE('📅 Year'!$C$6,6,1),'💳 Transactions'!$B$12:$B$5000,"<"&DATE('📅 Year'!$C$6,6+1,1)) | I11: =SUMIFS('💳 Transactions'!$J$12:$J$5000,'💳 Transactions'!$E$12:$E$5000,"Transportation",'💳 Transactions'!$B$12:$B$5000,">="&DATE('📅 Year'!$C$6,7,1),'💳 Transactions'!$B$12:$B$5000,"<"&DATE('📅 Year'!$C$6,7+1,1)) | J11: =SUMIFS('💳 Transactions'!$J$12:$J$5000,'💳 Transactions'!$E$12:$E$5000,"Transportation",'💳 Transactions'!$B$12:$B$5000,">="&DATE('📅 Year'!$C$6,8,1),'💳 Transactions'!$B$12:$B$5000,"<"&DATE('📅 Year'!$C$6,8+1,1)) | K11: =SUMIFS('💳 Transactions'!$J$12:$J$5000,'💳 Transactions'!$E$12:$E$5000,"Transportation",'💳 Transactions'!$B$12:$B$5000,">="&DATE('📅 Year'!$C$6,9,1),'💳 Transactions'!$B$12:$B$5000,"<"&DATE('📅 Year'!$C$6,9+1,1)) | L11: =SUMIFS('💳 Transactions'!$J$12:$J$5000,'💳 Transactions'!$E$12:$E$5000,"Transportation",'💳 Transactions'!$B$12:$B$5000,">="&DATE('📅 Year'!$C$6,10,1),'💳 Transactions'!$B$12:$B$5000,"<"&DATE('📅 Year'!$C$6,10+1,1)) | M11: =SUMIFS('💳 Transactions'!$J$12:$J$5000,'💳 Transactions'!$E$12:$E$5000,"Transportation",'💳 Transactions'!$B$12:$B$5000,">="&DATE('📅 Year'!$C$6,11,1),'💳 Transactions'!$B$12:$B$5000,"<"&DATE('📅 Year'!$C$6,11+1,1)) | N11: =SUMIFS('💳 Transactions'!$J$12:$J$5000,'💳 Transactions'!$E$12:$E$5000,"Transportation",'💳 Transactions'!$B$12:$B$5000,">="&DATE('📅 Year'!$C$6,12,1),'💳 Transactions'!$B$12:$B$5000,"<"&DATE('📅 Year'!$C$6,12+1,1)) | O11: =SUM(C11:N11)
B12: 🛍️ Shopping | C12: =SUMIFS('💳 Transactions'!$J$12:$J$5000,'💳 Transactions'!$E$12:$E$5000,"Shopping",'💳 Transactions'!$B$12:$B$5000,">="&DATE('📅 Year'!$C$6,1,1),'💳 Transactions'!$B$12:$B$5000,"<"&DATE('📅 Year'!$C$6,1+1,1)) | D12: =SUMIFS('💳 Transactions'!$J$12:$J$5000,'💳 Transactions'!$E$12:$E$5000,"Shopping",'💳 Transactions'!$B$12:$B$5000,">="&DATE('📅 Year'!$C$6,2,1),'💳 Transactions'!$B$12:$B$5000,"<"&DATE('📅 Year'!$C$6,2+1,1)) | E12: =SUMIFS('💳 Transactions'!$J$12:$J$5000,'💳 Transactions'!$E$12:$E$5000,"Shopping",'💳 Transactions'!$B$12:$B$5000,">="&DATE('📅 Year'!$C$6,3,1),'💳 Transactions'!$B$12:$B$5000,"<"&DATE('📅 Year'!$C$6,3+1,1)) | F12: =SUMIFS('💳 Transactions'!$J$12:$J$5000,'💳 Transactions'!$E$12:$E$5000,"Shopping",'💳 Transactions'!$B$12:$B$5000,">="&DATE('📅 Year'!$C$6,4,1),'💳 Transactions'!$B$12:$B$5000,"<"&DATE('📅 Year'!$C$6,4+1,1)) | G12: =SUMIFS('💳 Transactions'!$J$12:$J$5000,'💳 Transactions'!$E$12:$E$5000,"Shopping",'💳 Transactions'!$B$12:$B$5000,">="&DATE('📅 Year'!$C$6,5,1),'💳 Transactions'!$B$12:$B$5000,"<"&DATE('📅 Year'!$C$6,5+1,1)) | H12: =SUMIFS('💳 Transactions'!$J$12:$J$5000,'💳 Transactions'!$E$12:$E$5000,"Shopping",'💳 Transactions'!$B$12:$B$5000,">="&DATE('📅 Year'!$C$6,6,1),'💳 Transactions'!$B$12:$B$5000,"<"&DATE('📅 Year'!$C$6,6+1,1)) | I12: =SUMIFS('💳 Transactions'!$J$12:$J$5000,'💳 Transactions'!$E$12:$E$5000,"Shopping",'💳 Transactions'!$B$12:$B$5000,">="&DATE('📅 Year'!$C$6,7,1),'💳 Transactions'!$B$12:$B$5000,"<"&DATE('📅 Year'!$C$6,7+1,1)) | J12: =SUMIFS('💳 Transactions'!$J$12:$J$5000,'💳 Transactions'!$E$12:$E$5000,"Shopping",'💳 Transactions'!$B$12:$B$5000,">="&DATE('📅 Year'!$C$6,8,1),'💳 Transactions'!$B$12:$B$5000,"<"&DATE('📅 Year'!$C$6,8+1,1)) | K12: =SUMIFS('💳 Transactions'!$J$12:$J$5000,'💳 Transactions'!$E$12:$E$5000,"Shopping",'💳 Transactions'!$B$12:$B$5000,">="&DATE('📅 Year'!$C$6,9,1),'💳 Transactions'!$B$12:$B$5000,"<"&DATE('📅 Year'!$C$6,9+1,1)) | L12: =SUMIFS('💳 Transactions'!$J$12:$J$5000,'💳 Transactions'!$E$12:$E$5000,"Shopping",'💳 Transactions'!$B$12:$B$5000,">="&DATE('📅 Year'!$C$6,10,1),'💳 Transactions'!$B$12:$B$5000,"<"&DATE('📅 Year'!$C$6,10+1,1)) | M12: =SUMIFS('💳 Transactions'!$J$12:$J$5000,'💳 Transactions'!$E$12:$E$5000,"Shopping",'💳 Transactions'!$B$12:$B$5000,">="&DATE('📅 Year'!$C$6,11,1),'💳 Transactions'!$B$12:$B$5000,"<"&DATE('📅 Year'!$C$6,11+1,1)) | N12: =SUMIFS('💳 Transactions'!$J$12:$J$5000,'💳 Transactions'!$E$12:$E$5000,"Shopping",'💳 Transactions'!$B$12:$B$5000,">="&DATE('📅 Year'!$C$6,12,1),'💳 Transactions'!$B$12:$B$5000,"<"&DATE('📅 Year'!$C$6,12+1,1)) | O12: =SUM(C12:N12)
B13: 🎬 Entertainment | C13: =SUMIFS('💳 Transactions'!$J$12:$J$5000,'💳 Transactions'!$E$12:$E$5000,"Entertainment",'💳 Transactions'!$B$12:$B$5000,">="&DATE('📅 Year'!$C$6,1,1),'💳 Transactions'!$B$12:$B$5000,"<"&DATE('📅 Year'!$C$6,1+1,1)) | D13: =SUMIFS('💳 Transactions'!$J$12:$J$5000,'💳 Transactions'!$E$12:$E$5000,"Entertainment",'💳 Transactions'!$B$12:$B$5000,">="&DATE('📅 Year'!$C$6,2,1),'💳 Transactions'!$B$12:$B$5000,"<"&DATE('📅 Year'!$C$6,2+1,1)) | E13: =SUMIFS('💳 Transactions'!$J$12:$J$5000,'💳 Transactions'!$E$12:$E$5000,"Entertainment",'💳 Transactions'!$B$12:$B$5000,">="&DATE('📅 Year'!$C$6,3,1),'💳 Transactions'!$B$12:$B$5000,"<"&DATE('📅 Year'!$C$6,3+1,1)) | F13: =SUMIFS('💳 Transactions'!$J$12:$J$5000,'💳 Transactions'!$E$12:$E$5000,"Entertainment",'💳 Transactions'!$B$12:$B$5000,">="&DATE('📅 Year'!$C$6,4,1),'💳 Transactions'!$B$12:$B$5000,"<"&DATE('📅 Year'!$C$6,4+1,1)) | G13: =SUMIFS('💳 Transactions'!$J$12:$J$5000,'💳 Transactions'!$E$12:$E$5000,"Entertainment",'💳 Transactions'!$B$12:$B$5000,">="&DATE('📅 Year'!$C$6,5,1),'💳 Transactions'!$B$12:$B$5000,"<"&DATE('📅 Year'!$C$6,5+1,1)) | H13: =SUMIFS('💳 Transactions'!$J$12:$J$5000,'💳 Transactions'!$E$12:$E$5000,"Entertainment",'💳 Transactions'!$B$12:$B$5000,">="&DATE('📅 Year'!$C$6,6,1),'💳 Transactions'!$B$12:$B$5000,"<"&DATE('📅 Year'!$C$6,6+1,1)) | I13: =SUMIFS('💳 Transactions'!$J$12:$J$5000,'💳 Transactions'!$E$12:$E$5000,"Entertainment",'💳 Transactions'!$B$12:$B$5000,">="&DATE('📅 Year'!$C$6,7,1),'💳 Transactions'!$B$12:$B$5000,"<"&DATE('📅 Year'!$C$6,7+1,1)) | J13: =SUMIFS('💳 Transactions'!$J$12:$J$5000,'💳 Transactions'!$E$12:$E$5000,"Entertainment",'💳 Transactions'!$B$12:$B$5000,">="&DATE('📅 Year'!$C$6,8,1),'💳 Transactions'!$B$12:$B$5000,"<"&DATE('📅 Year'!$C$6,8+1,1)) | K13: =SUMIFS('💳 Transactions'!$J$12:$J$5000,'💳 Transactions'!$E$12:$E$5000,"Entertainment",'💳 Transactions'!$B$12:$B$5000,">="&DATE('📅 Year'!$C$6,9,1),'💳 Transactions'!$B$12:$B$5000,"<"&DATE('📅 Year'!$C$6,9+1,1)) | L13: =SUMIFS('💳 Transactions'!$J$12:$J$5000,'💳 Transactions'!$E$12:$E$5000,"Entertainment",'💳 Transactions'!$B$12:$B$5000,">="&DATE('📅 Year'!$C$6,10,1),'💳 Transactions'!$B$12:$B$5000,"<"&DATE('📅 Year'!$C$6,10+1,1)) | M13: =SUMIFS('💳 Transactions'!$J$12:$J$5000,'💳 Transactions'!$E$12:$E$5000,"Entertainment",'💳 Transactions'!$B$12:$B$5000,">="&DATE('📅 Year'!$C$6,11,1),'💳 Transactions'!$B$12:$B$5000,"<"&DATE('📅 Year'!$C$6,11+1,1)) | N13: =SUMIFS('💳 Transactions'!$J$12:$J$5000,'💳 Transactions'!$E$12:$E$5000,"Entertainment",'💳 Transactions'!$B$12:$B$5000,">="&DATE('📅 Year'!$C$6,12,1),'💳 Transactions'!$B$12:$B$5000,"<"&DATE('📅 Year'!$C$6,12+1,1)) | O13: =SUM(C13:N13)
B14: 🩺 Health | C14: =SUMIFS('💳 Transactions'!$J$12:$J$5000,'💳 Transactions'!$E$12:$E$5000,"Health",'💳 Transactions'!$B$12:$B$5000,">="&DATE('📅 Year'!$C$6,1,1),'💳 Transactions'!$B$12:$B$5000,"<"&DATE('📅 Year'!$C$6,1+1,1)) | D14: =SUMIFS('💳 Transactions'!$J$12:$J$5000,'💳 Transactions'!$E$12:$E$5000,"Health",'💳 Transactions'!$B$12:$B$5000,">="&DATE('📅 Year'!$C$6,2,1),'💳 Transactions'!$B$12:$B$5000,"<"&DATE('📅 Year'!$C$6,2+1,1)) | E14: =SUMIFS('💳 Transactions'!$J$12:$J$5000,'💳 Transactions'!$E$12:$E$5000,"Health",'💳 Transactions'!$B$12:$B$5000,">="&DATE('📅 Year'!$C$6,3,1),'💳 Transactions'!$B$12:$B$5000,"<"&DATE('📅 Year'!$C$6,3+1,1)) | F14: =SUMIFS('💳 Transactions'!$J$12:$J$5000,'💳 Transactions'!$E$12:$E$5000,"Health",'💳 Transactions'!$B$12:$B$5000,">="&DATE('📅 Year'!$C$6,4,1),'💳 Transactions'!$B$12:$B$5000,"<"&DATE('📅 Year'!$C$6,4+1,1)) | G14: =SUMIFS('💳 Transactions'!$J$12:$J$5000,'💳 Transactions'!$E$12:$E$5000,"Health",'💳 Transactions'!$B$12:$B$5000,">="&DATE('📅 Year'!$C$6,5,1),'💳 Transactions'!$B$12:$B$5000,"<"&DATE('📅 Year'!$C$6,5+1,1)) | H14: =SUMIFS('💳 Transactions'!$J$12:$J$5000,'💳 Transactions'!$E$12:$E$5000,"Health",'💳 Transactions'!$B$12:$B$5000,">="&DATE('📅 Year'!$C$6,6,1),'💳 Transactions'!$B$12:$B$5000,"<"&DATE('📅 Year'!$C$6,6+1,1)) | I14: =SUMIFS('💳 Transactions'!$J$12:$J$5000,'💳 Transactions'!$E$12:$E$5000,"Health",'💳 Transactions'!$B$12:$B$5000,">="&DATE('📅 Year'!$C$6,7,1),'💳 Transactions'!$B$12:$B$5000,"<"&DATE('📅 Year'!$C$6,7+1,1)) | J14: =SUMIFS('💳 Transactions'!$J$12:$J$5000,'💳 Transactions'!$E$12:$E$5000,"Health",'💳 Transactions'!$B$12:$B$5000,">="&DATE('📅 Year'!$C$6,8,1),'💳 Transactions'!$B$12:$B$5000,"<"&DATE('📅 Year'!$C$6,8+1,1)) | K14: =SUMIFS('💳 Transactions'!$J$12:$J$5000,'💳 Transactions'!$E$12:$E$5000,"Health",'💳 Transactions'!$B$12:$B$5000,">="&DATE('📅 Year'!$C$6,9,1),'💳 Transactions'!$B$12:$B$5000,"<"&DATE('📅 Year'!$C$6,9+1,1)) | L14: =SUMIFS('💳 Transactions'!$J$12:$J$5000,'💳 Transactions'!$E$12:$E$5000,"Health",'💳 Transactions'!$B$12:$B$5000,">="&DATE('📅 Year'!$C$6,10,1),'💳 Transactions'!$B$12:$B$5000,"<"&DATE('📅 Year'!$C$6,10+1,1)) | M14: =SUMIFS('💳 Transactions'!$J$12:$J$5000,'💳 Transactions'!$E$12:$E$5000,"Health",'💳 Transactions'!$B$12:$B$5000,">="&DATE('📅 Year'!$C$6,11,1),'💳 Transactions'!$B$12:$B$5000,"<"&DATE('📅 Year'!$C$6,11+1,1)) | N14: =SUMIFS('💳 Transactions'!$J$12:$J$5000,'💳 Transactions'!$E$12:$E$5000,"Health",'💳 Transactions'!$B$12:$B$5000,">="&DATE('📅 Year'!$C$6,12,1),'💳 Transactions'!$B$12:$B$5000,"<"&DATE('📅 Year'!$C$6,12+1,1)) | O14: =SUM(C14:N14)
B15: 🛡️ Insurance | C15: =SUMIFS('💳 Transactions'!$J$12:$J$5000,'💳 Transactions'!$E$12:$E$5000,"Insurance",'💳 Transactions'!$B$12:$B$5000,">="&DATE('📅 Year'!$C$6,1,1),'💳 Transactions'!$B$12:$B$5000,"<"&DATE('📅 Year'!$C$6,1+1,1)) | D15: =SUMIFS('💳 Transactions'!$J$12:$J$5000,'💳 Transactions'!$E$12:$E$5000,"Insurance",'💳 Transactions'!$B$12:$B$5000,">="&DATE('📅 Year'!$C$6,2,1),'💳 Transactions'!$B$12:$B$5000,"<"&DATE('📅 Year'!$C$6,2+1,1)) | E15: =SUMIFS('💳 Transactions'!$J$12:$J$5000,'💳 Transactions'!$E$12:$E$5000,"Insurance",'💳 Transactions'!$B$12:$B$5000,">="&DATE('📅 Year'!$C$6,3,1),'💳 Transactions'!$B$12:$B$5000,"<"&DATE('📅 Year'!$C$6,3+1,1)) | F15: =SUMIFS('💳 Transactions'!$J$12:$J$5000,'💳 Transactions'!$E$12:$E$5000,"Insurance",'💳 Transactions'!$B$12:$B$5000,">="&DATE('📅 Year'!$C$6,4,1),'💳 Transactions'!$B$12:$B$5000,"<"&DATE('📅 Year'!$C$6,4+1,1)) | G15: =SUMIFS('💳 Transactions'!$J$12:$J$5000,'💳 Transactions'!$E$12:$E$5000,"Insurance",'💳 Transactions'!$B$12:$B$5000,">="&DATE('📅 Year'!$C$6,5,1),'💳 Transactions'!$B$12:$B$5000,"<"&DATE('📅 Year'!$C$6,5+1,1)) | H15: =SUMIFS('💳 Transactions'!$J$12:$J$5000,'💳 Transactions'!$E$12:$E$5000,"Insurance",'💳 Transactions'!$B$12:$B$5000,">="&DATE('📅 Year'!$C$6,6,1),'💳 Transactions'!$B$12:$B$5000,"<"&DATE('📅 Year'!$C$6,6+1,1)) | I15: =SUMIFS('💳 Transactions'!$J$12:$J$5000,'💳 Transactions'!$E$12:$E$5000,"Insurance",'💳 Transactions'!$B$12:$B$5000,">="&DATE('📅 Year'!$C$6,7,1),'💳 Transactions'!$B$12:$B$5000,"<"&DATE('📅 Year'!$C$6,7+1,1)) | J15: =SUMIFS('💳 Transactions'!$J$12:$J$5000,'💳 Transactions'!$E$12:$E$5000,"Insurance",'💳 Transactions'!$B$12:$B$5000,">="&DATE('📅 Year'!$C$6,8,1),'💳 Transactions'!$B$12:$B$5000,"<"&DATE('📅 Year'!$C$6,8+1,1)) | K15: =SUMIFS('💳 Transactions'!$J$12:$J$5000,'💳 Transactions'!$E$12:$E$5000,"Insurance",'💳 Transactions'!$B$12:$B$5000,">="&DATE('📅 Year'!$C$6,9,1),'💳 Transactions'!$B$12:$B$5000,"<"&DATE('📅 Year'!$C$6,9+1,1)) | L15: =SUMIFS('💳 Transactions'!$J$12:$J$5000,'💳 Transactions'!$E$12:$E$5000,"Insurance",'💳 Transactions'!$B$12:$B$5000,">="&DATE('📅 Year'!$C$6,10,1),'💳 Transactions'!$B$12:$B$5000,"<"&DATE('📅 Year'!$C$6,10+1,1)) | M15: =SUMIFS('💳 Transactions'!$J$12:$J$5000,'💳 Transactions'!$E$12:$E$5000,"Insurance",'💳 Transactions'!$B$12:$B$5000,">="&DATE('📅 Year'!$C$6,11,1),'💳 Transactions'!$B$12:$B$5000,"<"&DATE('📅 Year'!$C$6,11+1,1)) | N15: =SUMIFS('💳 Transactions'!$J$12:$J$5000,'💳 Transactions'!$E$12:$E$5000,"Insurance",'💳 Transactions'!$B$12:$B$5000,">="&DATE('📅 Year'!$C$6,12,1),'💳 Transactions'!$B$12:$B$5000,"<"&DATE('📅 Year'!$C$6,12+1,1)) | O15: =SUM(C15:N15)
B16: ✈️ Travel | C16: =SUMIFS('💳 Transactions'!$J$12:$J$5000,'💳 Transactions'!$E$12:$E$5000,"Travel",'💳 Transactions'!$B$12:$B$5000,">="&DATE('📅 Year'!$C$6,1,1),'💳 Transactions'!$B$12:$B$5000,"<"&DATE('📅 Year'!$C$6,1+1,1)) | D16: =SUMIFS('💳 Transactions'!$J$12:$J$5000,'💳 Transactions'!$E$12:$E$5000,"Travel",'💳 Transactions'!$B$12:$B$5000,">="&DATE('📅 Year'!$C$6,2,1),'💳 Transactions'!$B$12:$B$5000,"<"&DATE('📅 Year'!$C$6,2+1,1)) | E16: =SUMIFS('💳 Transactions'!$J$12:$J$5000,'💳 Transactions'!$E$12:$E$5000,"Travel",'💳 Transactions'!$B$12:$B$5000,">="&DATE('📅 Year'!$C$6,3,1),'💳 Transactions'!$B$12:$B$5000,"<"&DATE('📅 Year'!$C$6,3+1,1)) | F16: =SUMIFS('💳 Transactions'!$J$12:$J$5000,'💳 Transactions'!$E$12:$E$5000,"Travel",'💳 Transactions'!$B$12:$B$5000,">="&DATE('📅 Year'!$C$6,4,1),'💳 Transactions'!$B$12:$B$5000,"<"&DATE('📅 Year'!$C$6,4+1,1)) | G16: =SUMIFS('💳 Transactions'!$J$12:$J$5000,'💳 Transactions'!$E$12:$E$5000,"Travel",'💳 Transactions'!$B$12:$B$5000,">="&DATE('📅 Year'!$C$6,5,1),'💳 Transactions'!$B$12:$B$5000,"<"&DATE('📅 Year'!$C$6,5+1,1)) | H16: =SUMIFS('💳 Transactions'!$J$12:$J$5000,'💳 Transactions'!$E$12:$E$5000,"Travel",'💳 Transactions'!$B$12:$B$5000,">="&DATE('📅 Year'!$C$6,6,1),'💳 Transactions'!$B$12:$B$5000,"<"&DATE('📅 Year'!$C$6,6+1,1)) | I16: =SUMIFS('💳 Transactions'!$J$12:$J$5000,'💳 Transactions'!$E$12:$E$5000,"Travel",'💳 Transactions'!$B$12:$B$5000,">="&DATE('📅 Year'!$C$6,7,1),'💳 Transactions'!$B$12:$B$5000,"<"&DATE('📅 Year'!$C$6,7+1,1)) | J16: =SUMIFS('💳 Transactions'!$J$12:$J$5000,'💳 Transactions'!$E$12:$E$5000,"Travel",'💳 Transactions'!$B$12:$B$5000,">="&DATE('📅 Year'!$C$6,8,1),'💳 Transactions'!$B$12:$B$5000,"<"&DATE('📅 Year'!$C$6,8+1,1)) | K16: =SUMIFS('💳 Transactions'!$J$12:$J$5000,'💳 Transactions'!$E$12:$E$5000,"Travel",'💳 Transactions'!$B$12:$B$5000,">="&DATE('📅 Year'!$C$6,9,1),'💳 Transactions'!$B$12:$B$5000,"<"&DATE('📅 Year'!$C$6,9+1,1)) | L16: =SUMIFS('💳 Transactions'!$J$12:$J$5000,'💳 Transactions'!$E$12:$E$5000,"Travel",'💳 Transactions'!$B$12:$B$5000,">="&DATE('📅 Year'!$C$6,10,1),'💳 Transactions'!$B$12:$B$5000,"<"&DATE('📅 Year'!$C$6,10+1,1)) | M16: =SUMIFS('💳 Transactions'!$J$12:$J$5000,'💳 Transactions'!$E$12:$E$5000,"Travel",'💳 Transactions'!$B$12:$B$5000,">="&DATE('📅 Year'!$C$6,11,1),'💳 Transactions'!$B$12:$B$5000,"<"&DATE('📅 Year'!$C$6,11+1,1)) | N16: =SUMIFS('💳 Transactions'!$J$12:$J$5000,'💳 Transactions'!$E$12:$E$5000,"Travel",'💳 Transactions'!$B$12:$B$5000,">="&DATE('📅 Year'!$C$6,12,1),'💳 Transactions'!$B$12:$B$5000,"<"&DATE('📅 Year'!$C$6,12+1,1)) | O16: =SUM(C16:N16)
B17: 🎓 Education | C17: =SUMIFS('💳 Transactions'!$J$12:$J$5000,'💳 Transactions'!$E$12:$E$5000,"Education",'💳 Transactions'!$B$12:$B$5000,">="&DATE('📅 Year'!$C$6,1,1),'💳 Transactions'!$B$12:$B$5000,"<"&DATE('📅 Year'!$C$6,1+1,1)) | D17: =SUMIFS('💳 Transactions'!$J$12:$J$5000,'💳 Transactions'!$E$12:$E$5000,"Education",'💳 Transactions'!$B$12:$B$5000,">="&DATE('📅 Year'!$C$6,2,1),'💳 Transactions'!$B$12:$B$5000,"<"&DATE('📅 Year'!$C$6,2+1,1)) | E17: =SUMIFS('💳 Transactions'!$J$12:$J$5000,'💳 Transactions'!$E$12:$E$5000,"Education",'💳 Transactions'!$B$12:$B$5000,">="&DATE('📅 Year'!$C$6,3,1),'💳 Transactions'!$B$12:$B$5000,"<"&DATE('📅 Year'!$C$6,3+1,1)) | F17: =SUMIFS('💳 Transactions'!$J$12:$J$5000,'💳 Transactions'!$E$12:$E$5000,"Education",'💳 Transactions'!$B$12:$B$5000,">="&DATE('📅 Year'!$C$6,4,1),'💳 Transactions'!$B$12:$B$5000,"<"&DATE('📅 Year'!$C$6,4+1,1)) | G17: =SUMIFS('💳 Transactions'!$J$12:$J$5000,'💳 Transactions'!$E$12:$E$5000,"Education",'💳 Transactions'!$B$12:$B$5000,">="&DATE('📅 Year'!$C$6,5,1),'💳 Transactions'!$B$12:$B$5000,"<"&DATE('📅 Year'!$C$6,5+1,1)) | H17: =SUMIFS('💳 Transactions'!$J$12:$J$5000,'💳 Transactions'!$E$12:$E$5000,"Education",'💳 Transactions'!$B$12:$B$5000,">="&DATE('📅 Year'!$C$6,6,1),'💳 Transactions'!$B$12:$B$5000,"<"&DATE('📅 Year'!$C$6,6+1,1)) | I17: =SUMIFS('💳 Transactions'!$J$12:$J$5000,'💳 Transactions'!$E$12:$E$5000,"Education",'💳 Transactions'!$B$12:$B$5000,">="&DATE('📅 Year'!$C$6,7,1),'💳 Transactions'!$B$12:$B$5000,"<"&DATE('📅 Year'!$C$6,7+1,1)) | J17: =SUMIFS('💳 Transactions'!$J$12:$J$5000,'💳 Transactions'!$E$12:$E$5000,"Education",'💳 Transactions'!$B$12:$B$5000,">="&DATE('📅 Year'!$C$6,8,1),'💳 Transactions'!$B$12:$B$5000,"<"&DATE('📅 Year'!$C$6,8+1,1)) | K17: =SUMIFS('💳 Transactions'!$J$12:$J$5000,'💳 Transactions'!$E$12:$E$5000,"Education",'💳 Transactions'!$B$12:$B$5000,">="&DATE('📅 Year'!$C$6,9,1),'💳 Transactions'!$B$12:$B$5000,"<"&DATE('📅 Year'!$C$6,9+1,1)) | L17: =SUMIFS('💳 Transactions'!$J$12:$J$5000,'💳 Transactions'!$E$12:$E$5000,"Education",'💳 Transactions'!$B$12:$B$5000,">="&DATE('📅 Year'!$C$6,10,1),'💳 Transactions'!$B$12:$B$5000,"<"&DATE('📅 Year'!$C$6,10+1,1)) | M17: =SUMIFS('💳 Transactions'!$J$12:$J$5000,'💳 Transactions'!$E$12:$E$5000,"Education",'💳 Transactions'!$B$12:$B$5000,">="&DATE('📅 Year'!$C$6,11,1),'💳 Transactions'!$B$12:$B$5000,"<"&DATE('📅 Year'!$C$6,11+1,1)) | N17: =SUMIFS('💳 Transactions'!$J$12:$J$5000,'💳 Transactions'!$E$12:$E$5000,"Education",'💳 Transactions'!$B$12:$B$5000,">="&DATE('📅 Year'!$C$6,12,1),'💳 Transactions'!$B$12:$B$5000,"<"&DATE('📅 Year'!$C$6,12+1,1)) | O17: =SUM(C17:N17)
